<sdf version='1.7'>
  <world name='default'>
    <light name='sun' type='directional'>
      <cast_shadows>1</cast_shadows>
      <pose>0 0 10 0 -0 0</pose>
      <diffuse>0.8 0.8 0.8 1</diffuse>
      <specular>0.2 0.2 0.2 1</specular>
      <attenuation>
        <range>1000</range>
        <constant>0.9</constant>
        <linear>0.01</linear>
        <quadratic>0.001</quadratic>
      </attenuation>
      <direction>-0.5 0.1 -0.9</direction>
      <spot>
        <inner_angle>0</inner_angle>
        <outer_angle>0</outer_angle>
        <falloff>0</falloff>
      </spot>
    </light>
    <model name='ground_plane'>
      <static>1</static>
      <link name='link'>
        <collision name='collision'>
          <geometry>
            <plane>
              <normal>0 0 1</normal>
              <size>100 100</size>
            </plane>
          </geometry>
          <surface>
            <contact>
              <collide_bitmask>65535</collide_bitmask>
              <ode/>
            </contact>
            <friction>
              <ode>
                <mu>100</mu>
                <mu2>50</mu2>
              </ode>
              <torsional>
                <ode/>
              </torsional>
            </friction>
            <bounce/>
          </surface>
          <max_contacts>10</max_contacts>
        </collision>
        <visual name='visual'>
          <cast_shadows>0</cast_shadows>
          <geometry>
            <plane>
              <normal>0 0 1</normal>
              <size>100 100</size>
            </plane>
          </geometry>
          <material>
            <script>
              <uri>file://media/materials/scripts/gazebo.material</uri>
              <name>Gazebo/Grey</name>
            </script>
          </material>
        </visual>
        <self_collide>0</self_collide>
        <enable_wind>0</enable_wind>
        <kinematic>0</kinematic>
      </link>
    </model>
    <gravity>0 0 -9.8</gravity>
    <magnetic_field>6e-06 2.3e-05 -4.2e-05</magnetic_field>
    <atmosphere type='adiabatic'/>
    <physics type='ode'>
      <max_step_size>0.001</max_step_size>
      <real_time_factor>1</real_time_factor>
      <real_time_update_rate>1000</real_time_update_rate>
    </physics>
    <scene>
      <ambient>0.4 0.4 0.4 1</ambient>
      <background>0.7 0.7 0.7 1</background>
      <shadows>1</shadows>
    </scene>
    <audio>
      <device>default</device>
    </audio>
    <wind/>
    <spherical_coordinates>
      <surface_model>EARTH_WGS84</surface_model>
      <latitude_deg>0</latitude_deg>
      <longitude_deg>0</longitude_deg>
      <elevation>0</elevation>
      <heading_deg>0</heading_deg>
    </spherical_coordinates>
    <model name='bobo_standalone'>
      <link name='base_footprint'>
        <inertial>
          <pose>0.014375 -1.1e-05 0.184857 0 -0 0</pose>
          <mass>2.0561</mass>
          <inertia>
            <ixx>0.017616</ixx>
            <ixy>-2.53475e-07</ixy>
            <ixz>-0.00142734</ixz>
            <iyy>0.0237538</iyy>
            <iyz>-5.34721e-08</iyz>
            <izz>0.0361588</izz>
          </inertia>
        </inertial>
        <collision name='base_footprint_fixed_joint_lump__base_link_collision'>
          <pose>0 0 0 0 -0 0</pose>
          <geometry>
            <mesh>
              <scale>1 1 1</scale>
              <uri>/ros2_ws/src/rom_robot_class/bobo_description/meshes/base_link.STL</uri>
            </mesh>
          </geometry>
          <max_contacts>10</max_contacts>
          <surface>
            <contact>
              <ode/>
            </contact>
            <bounce/>
            <friction>
              <torsional>
                <ode/>
              </torsional>
              <ode/>
            </friction>
          </surface>
        </collision>
        <collision name='base_footprint_fixed_joint_lump__laser_link_collision_1'>
          <pose>0.195 0 0.2465 3.14159 -0 0</pose>
          <geometry>
            <cylinder>
              <length>0.0315</length>
              <radius>0.055</radius>
            </cylinder>
          </geometry>
          <surface>
            <contact>
              <ode/>
            </contact>
            <friction>
              <ode/>
              <torsional>
                <ode/>
              </torsional>
            </friction>
            <bounce/>
          </surface>
          <max_contacts>10</max_contacts>
        </collision>
        <visual name='base_footprint_fixed_joint_lump__base_link_visual'>
          <pose>0 0 0 0 -0 0</pose>
          <geometry>
            <mesh>
              <scale>1 1 1</scale>
              <uri>/ros2_ws/src/rom_robot_class/bobo_description/meshes/base_link.STL</uri>
            </mesh>
          </geometry>
        </visual>
        <visual name='base_footprint_fixed_joint_lump__cam3d_left_link_visual_1'>
          <pose>0 0.3 0.5 0 -0 0</pose>
          <geometry>
            <box>
              <size>0.03 0.02 0.02</size>
            </box>
          </geometry>
        </visual>
        <visual name='base_footprint_fixed_joint_lump__cam3d_right_link_visual_2'>
          <pose>0 -0.3 0.5 0 -0 0</pose>
          <geometry>
            <box>
              <size>0.03 0.02 0.02</size>
            </box>
          </geometry>
        </visual>
        <visual name='base_footprint_fixed_joint_lump__cam3d_top_link_visual_3'>
          <pose>0.15 0 0.8 0 -0 0</pose>
          <geometry>
            <box>
              <size>0.03 0.02 0.02</size>
            </box>
          </geometry>
        </visual>
        <visual name='base_footprint_fixed_joint_lump__imu_link_visual_4'>
          <pose>0 0 0.268 0 -0 0</pose>
          <geometry>
            <box>
              <size>0.03 0.02 0.02</size>
            </box>
          </geometry>
        </visual>
        <visual name='base_footprint_fixed_joint_lump__laser_link_visual_5'>
          <pose>0.18 0 0.24 3.14159 -0 0</pose>
          <geometry>
            <box>
              <size>0.05 0.05 0.05</size>
            </box>
          </geometry>
          <material>
            <script>
              <name>Gazebo/Red</name>
              <uri>file://media/materials/scripts/gazebo.material</uri>
            </script>
          </material>
        </visual>
        <gravity>1</gravity>
        <sensor name='imu_sensor' type='imu'>
          <always_on>1</always_on>
          <update_rate>20</update_rate>
          <visualize>1</visualize>
          <topic>/imu</topic>
          <plugin name='imu_plugin' filename='libgazebo_ros_imu_sensor.so'>
            <topicName>imu</topicName>
            <bodyName>imu_link</bodyName>
            <updateRateHZ>10.0</updateRateHZ>
            <gaussianNoise>0.0</gaussianNoise>
            <xyzOffset>0 0 0</xyzOffset>
            <rpyOffset>0 0 0</rpyOffset>
            <frameName>imu_link</frameName>
            <initialOrientationAsReference>0</initialOrientationAsReference>
          </plugin>
          <pose>0 0 0.268 0 -0 0</pose>
          <imu/>
        </sensor>
        <sensor name='laser' type='ray'>
          <visualize>1</visualize>
          <update_rate>10</update_rate>
          <ray>
            <scan>
              <horizontal>
                <samples>360</samples>
                <resolution>1</resolution>
                <min_angle>-2.3562</min_angle>
                <max_angle>2.3562</max_angle>
              </horizontal>
              <vertical>
                <samples>1</samples>
                <min_angle>0</min_angle>
                <max_angle>0</max_angle>
              </vertical>
            </scan>
            <range>
              <min>0.05</min>
              <max>12</max>
              <resolution>0.01</resolution>
            </range>
          </ray>
          <plugin name='laser_controller' filename='libgazebo_ros_ray_sensor.so'>
            <ros>
              <argument>~/out:=scan</argument>
            </ros>
            <output_type>sensor_msgs/LaserScan</output_type>
            <frame_name>laser_link</frame_name>
          </plugin>
          <pose>0.18 0 0.24 3.14159 -0 0</pose>
        </sensor>
        <self_collide>0</self_collide>
        <enable_wind>0</enable_wind>
        <kinematic>0</kinematic>
      </link>
      <joint name='caster_back_left_joint' type='revolute'>
        <pose relative_to='base_footprint'>-0.16676 0.077762 0.016 0 -0 0.43633</pose>
        <parent>base_footprint</parent>
        <child>caster_back_left_link</child>
        <axis>
          <xyz>-0.087156 -0.99619 0</xyz>
          <limit>
            <lower>-1e+16</lower>
            <upper>1e+16</upper>
          </limit>
          <dynamics>
            <spring_reference>0</spring_reference>
            <spring_stiffness>0</spring_stiffness>
          </dynamics>
        </axis>
      </joint>
      <link name='caster_back_left_link'>
        <pose relative_to='caster_back_left_joint'>0 0 0 0 -0 0</pose>
        <inertial>
          <pose>0 0 0 0 -0 0</pose>
          <mass>0.0103872</mass>
          <inertia>
            <ixx>9.76068e-07</ixx>
            <ixy>4.37498e-08</ixy>
            <ixz>-3.74882e-14</ixz>
            <iyy>1.4723e-06</iyy>
            <iyz>-4.28493e-13</iyz>
            <izz>9.72241e-07</izz>
          </inertia>
        </inertial>
        <collision name='caster_back_left_link_collision'>
          <pose>0 0 0 0 -0 0</pose>
          <geometry>
            <mesh>
              <scale>1 1 1</scale>
              <uri>/ros2_ws/src/rom_robot_class/bobo_description/meshes/caster_back_left_link.STL</uri>
            </mesh>
          </geometry>
          <max_contacts>10</max_contacts>
          <surface>
            <contact>
              <ode/>
            </contact>
            <bounce/>
            <friction>
              <torsional>
                <ode/>
              </torsional>
              <ode/>
            </friction>
          </surface>
        </collision>
        <visual name='caster_back_left_link_visual'>
          <pose>0 0 0 0 -0 0</pose>
          <geometry>
            <mesh>
              <scale>1 1 1</scale>
              <uri>/ros2_ws/src/rom_robot_class/bobo_description/meshes/caster_back_left_link.STL</uri>
            </mesh>
          </geometry>
        </visual>
        <self_collide>0</self_collide>
        <enable_wind>0</enable_wind>
        <kinematic>0</kinematic>
      </link>
      <joint name='caster_back_right_joint' type='revolute'>
        <pose relative_to='base_footprint'>-0.16676 -0.077762 0.016 0 0 -0.43633</pose>
        <parent>base_footprint</parent>
        <child>caster_back_right_link</child>
        <axis>
          <xyz>0.087156 -0.99619 0</xyz>
          <limit>
            <lower>-1e+16</lower>
            <upper>1e+16</upper>
          </limit>
          <dynamics>
            <spring_reference>0</spring_reference>
            <spring_stiffness>0</spring_stiffness>
          </dynamics>
        </axis>
      </joint>
      <link name='caster_back_right_link'>
        <pose relative_to='caster_back_right_joint'>0 0 0 0 -0 0</pose>
        <inertial>
          <pose>-0 0 0 0 -0 0</pose>
          <mass>0.0103872</mass>
          <inertia>
            <ixx>9.76068e-07</ixx>
            <ixy>-4.375e-08</ixy>
            <ixz>4.36232e-23</ixz>
            <iyy>1.4723e-06</iyy>
            <iyz>-5.74331e-22</iyz>
            <izz>9.72241e-07</izz>
          </inertia>
        </inertial>
        <collision name='caster_back_right_link_collision'>
          <pose>0 0 0 0 -0 0</pose>
          <geometry>
            <mesh>
              <scale>1 1 1</scale>
              <uri>/ros2_ws/src/rom_robot_class/bobo_description/meshes/caster_back_right_link.STL</uri>
            </mesh>
          </geometry>
          <max_contacts>10</max_contacts>
          <surface>
            <contact>
              <ode/>
            </contact>
            <bounce/>
            <friction>
              <torsional>
                <ode/>
              </torsional>
              <ode/>
            </friction>
          </surface>
        </collision>
        <visual name='caster_back_right_link_visual'>
          <pose>0 0 0 0 -0 0</pose>
          <geometry>
            <mesh>
              <scale>1 1 1</scale>
              <uri>/ros2_ws/src/rom_robot_class/bobo_description/meshes/caster_back_right_link.STL</uri>
            </mesh>
          </geometry>
        </visual>
        <self_collide>0</self_collide>
        <enable_wind>0</enable_wind>
        <kinematic>0</kinematic>
      </link>
      <joint name='caster_front_left_joint' type='revolute'>
        <pose relative_to='base_footprint'>0.16676 0.077762 0.016 0 0 -0.43633</pose>
        <parent>base_footprint</parent>
        <child>caster_front_left_link</child>
        <axis>
          <xyz>0.087156 -0.99619 0</xyz>
          <limit>
            <lower>-1e+16</lower>
            <upper>1e+16</upper>
          </limit>
          <dynamics>
            <spring_reference>0</spring_reference>
            <spring_stiffness>0</spring_stiffness>
          </dynamics>
        </axis>
      </joint>
      <link name='caster_front_left_link'>
        <pose relative_to='caster_front_left_joint'>0 0 0 0 -0 0</pose>
        <inertial>
          <pose>-0 -0 0 0 -0 0</pose>
          <mass>0.0103872</mass>
          <inertia>
            <ixx>9.76068e-07</ixx>
            <ixy>-4.375e-08</ixy>
            <ixz>3.49243e-23</ixz>
            <iyy>1.4723e-06</iyy>
            <iyz>-6.51907e-22</iyz>
            <izz>9.72241e-07</izz>
          </inertia>
        </inertial>
        <collision name='caster_front_left_link_collision'>
          <pose>0 0 0 0 -0 0</pose>
          <geometry>
            <mesh>
              <scale>1 1 1</scale>
              <uri>/ros2_ws/src/rom_robot_class/bobo_description/meshes/caster_front_left_link.STL</uri>
            </mesh>
          </geometry>
          <max_contacts>10</max_contacts>
          <surface>
            <contact>
              <ode/>
            </contact>
            <bounce/>
            <friction>
              <torsional>
                <ode/>
              </torsional>
              <ode/>
            </friction>
          </surface>
        </collision>
        <visual name='caster_front_left_link_visual'>
          <pose>0 0 0 0 -0 0</pose>
          <geometry>
            <mesh>
              <scale>1 1 1</scale>
              <uri>/ros2_ws/src/rom_robot_class/bobo_description/meshes/caster_front_left_link.STL</uri>
            </mesh>
          </geometry>
        </visual>
        <self_collide>0</self_collide>
        <enable_wind>0</enable_wind>
        <kinematic>0</kinematic>
      </link>
      <joint name='caster_front_right_joint' type='revolute'>
        <pose relative_to='base_footprint'>0.16676 -0.077762 0.016 0 -0 0.43633</pose>
        <parent>base_footprint</parent>
        <child>caster_front_right_link</child>
        <axis>
          <xyz>-0.087156 -0.99619 0</xyz>
          <limit>
            <lower>-1e+16</lower>
            <upper>1e+16</upper>
          </limit>
          <dynamics>
            <spring_reference>0</spring_reference>
            <spring_stiffness>0</spring_stiffness>
          </dynamics>
        </axis>
      </joint>
      <link name='caster_front_right_link'>
        <pose relative_to='caster_front_right_joint'>0 0 0 0 -0 0</pose>
        <inertial>
          <pose>-0 -0 -0 0 -0 0</pose>
          <mass>0.0103872</mass>
          <inertia>
            <ixx>9.76068e-07</ixx>
            <ixy>4.37488e-08</ixy>
            <ixz>4.36669e-23</ixz>
            <iyy>1.4723e-06</iyy>
            <iyz>5.4067e-22</iyz>
            <izz>9.72241e-07</izz>
          </inertia>
        </inertial>
        <collision name='caster_front_right_link_collision'>
          <pose>0 0 0 0 -0 0</pose>
          <geometry>
            <mesh>
              <scale>1 1 1</scale>
              <uri>/ros2_ws/src/rom_robot_class/bobo_description/meshes/caster_front_right_link.STL</uri>
            </mesh>
          </geometry>
          <max_contacts>10</max_contacts>
          <surface>
            <contact>
              <ode/>
            </contact>
            <bounce/>
            <friction>
              <torsional>
                <ode/>
              </torsional>
              <ode/>
            </friction>
          </surface>
        </collision>
        <visual name='caster_front_right_link_visual'>
          <pose>0 0 0 0 -0 0</pose>
          <geometry>
            <mesh>
              <scale>1 1 1</scale>
              <uri>/ros2_ws/src/rom_robot_class/bobo_description/meshes/caster_front_right_link.STL</uri>
            </mesh>
          </geometry>
        </visual>
        <self_collide>0</self_collide>
        <enable_wind>0</enable_wind>
        <kinematic>0</kinematic>
      </link>
      <joint name='left_wheel_joint' type='revolute'>
        <pose relative_to='base_footprint'>-0.0005 0.17971 0.0854 0 -0 0</pose>
        <parent>base_footprint</parent>
        <child>left_wheel_link</child>
        <axis>
          <xyz>0 -1 0</xyz>
          <limit>
            <lower>-1e+16</lower>
            <upper>1e+16</upper>
          </limit>
          <dynamics>
            <spring_reference>0</spring_reference>
            <spring_stiffness>0</spring_stiffness>
          </dynamics>
        </axis>
      </joint>
      <link name='left_wheel_link'>
        <pose relative_to='left_wheel_joint'>0 0 0 0 -0 0</pose>
        <inertial>
          <pose>0 -0.002611 0 0 -0 0</pose>
          <mass>1.13468</mass>
          <inertia>
            <ixx>0.00214378</ixx>
            <ixy>2.09699e-09</ixy>
            <ixz>-4.27899e-12</ixz>
            <iyy>0.00371289</iyy>
            <iyz>-3.46407e-10</iyz>
            <izz>0.00214378</izz>
          </inertia>
        </inertial>
        <collision name='left_wheel_link_collision'>
          <pose>0 0 0 0 -0 0</pose>
          <geometry>
            <mesh>
              <scale>1 1 1</scale>
              <uri>/ros2_ws/src/rom_robot_class/bobo_description/meshes/wheel_left_link.STL</uri>
            </mesh>
          </geometry>
          <max_contacts>10</max_contacts>
          <surface>
            <contact>
              <ode/>
            </contact>
            <bounce/>
            <friction>
              <torsional>
                <ode/>
              </torsional>
              <ode/>
            </friction>
          </surface>
        </collision>
        <visual name='left_wheel_link_visual'>
          <pose>0 0 0 0 -0 0</pose>
          <geometry>
            <mesh>
              <scale>1 1 1</scale>
              <uri>/ros2_ws/src/rom_robot_class/bobo_description/meshes/wheel_left_link.STL</uri>
            </mesh>
          </geometry>
        </visual>
        <self_collide>0</self_collide>
        <enable_wind>0</enable_wind>
        <kinematic>0</kinematic>
      </link>
      <joint name='right_wheel_joint' type='revolute'>
        <pose relative_to='base_footprint'>-0.0005 -0.17971 0.0854 0 -0 0</pose>
        <parent>base_footprint</parent>
        <child>right_wheel_link</child>
        <axis>
          <xyz>0 -1 0</xyz>
          <limit>
            <lower>-1e+16</lower>
            <upper>1e+16</upper>
          </limit>
          <dynamics>
            <spring_reference>0</spring_reference>
            <spring_stiffness>0</spring_stiffness>
          </dynamics>
        </axis>
      </joint>
      <link name='right_wheel_link'>
        <pose relative_to='right_wheel_joint'>0 0 0 0 -0 0</pose>
        <inertial>
          <pose>-0 0.002611 0 0 -0 0</pose>
          <mass>1.13468</mass>
          <inertia>
            <ixx>0.00214378</ixx>
            <ixy>1.35474e-09</ixy>
            <ixz>-1.11199e-11</ixz>
            <iyy>0.00371289</iyy>
            <iyz>-1.6377e-09</iyz>
            <izz>0.00214378</izz>
          </inertia>
        </inertial>
        <collision name='right_wheel_link_collision'>
          <pose>0 0 0 0 -0 0</pose>
          <geometry>
            <mesh>
              <scale>1 1 1</scale>
              <uri>/ros2_ws/src/rom_robot_class/bobo_description/meshes/wheel_right_link.STL</uri>
            </mesh>
          </geometry>
          <max_contacts>10</max_contacts>
          <surface>
            <contact>
              <ode/>
            </contact>
            <bounce/>
            <friction>
              <torsional>
                <ode/>
              </torsional>
              <ode/>
            </friction>
          </surface>
        </collision>
        <visual name='right_wheel_link_visual'>
          <pose>0 0 0 0 -0 0</pose>
          <geometry>
            <mesh>
              <scale>1 1 1</scale>
              <uri>/ros2_ws/src/rom_robot_class/bobo_description/meshes/wheel_right_link.STL</uri>
            </mesh>
          </geometry>
        </visual>
        <self_collide>0</self_collide>
        <enable_wind>0</enable_wind>
        <kinematic>0</kinematic>
      </link>
      <static>0</static>
      <plugin name='gazebo_ros2_control' filename='libgazebo_ros2_control.so'>
        <robot_param>robot_description</robot_param>
        <robot_param_node>robot_state_publisher</robot_param_node>
        <parameters>/ros2_ws/src/rom_robot_class/bobo_description/sim_config/my_controllers.yaml</parameters>
        <odometry_frame>odom</odometry_frame>
        <robot_base_frame>base_footprint</robot_base_frame>
        <publish_odom>1</publish_odom>
        <publish_odom_tf>1</publish_odom_tf>
        <publish_wheel_tf>1</publish_wheel_tf>
      </plugin>
      <pose>0 0 0.3 0 -0 0</pose>
    </model>
    <model name='unit_box'>
      <pose>1.81408 -0.506583 0.5 0 -0 0</pose>
      <link name='link'>
        <inertial>
          <mass>1</mass>
          <inertia>
            <ixx>0.166667</ixx>
            <ixy>0</ixy>
            <ixz>0</ixz>
            <iyy>0.166667</iyy>
            <iyz>0</iyz>
            <izz>0.166667</izz>
          </inertia>
          <pose>0 0 0 0 -0 0</pose>
        </inertial>
        <collision name='collision'>
          <geometry>
            <box>
              <size>1 1 1</size>
            </box>
          </geometry>
          <max_contacts>10</max_contacts>
          <surface>
            <contact>
              <ode/>
            </contact>
            <bounce/>
            <friction>
              <torsional>
                <ode/>
              </torsional>
              <ode/>
            </friction>
          </surface>
        </collision>
        <visual name='visual'>
          <geometry>
            <box>
              <size>1 1 1</size>
            </box>
          </geometry>
          <material>
            <script>
              <name>Gazebo/Grey</name>
              <uri>file://media/materials/scripts/gazebo.material</uri>
            </script>
          </material>
        </visual>
        <self_collide>0</self_collide>
        <enable_wind>0</enable_wind>
        <kinematic>0</kinematic>
      </link>
    </model>
    <model name='unit_box_0'>
      <pose>1.8307 0.6733 0.5 0 -0 0</pose>
      <link name='link'>
        <inertial>
          <mass>1</mass>
          <inertia>
            <ixx>0.166667</ixx>
            <ixy>0</ixy>
            <ixz>0</ixz>
            <iyy>0.166667</iyy>
            <iyz>0</iyz>
            <izz>0.166667</izz>
          </inertia>
          <pose>0 0 0 0 -0 0</pose>
        </inertial>
        <collision name='collision'>
          <geometry>
            <box>
              <size>1 1 1</size>
            </box>
          </geometry>
          <max_contacts>10</max_contacts>
          <surface>
            <contact>
              <ode/>
            </contact>
            <bounce/>
            <friction>
              <torsional>
                <ode/>
              </torsional>
              <ode/>
            </friction>
          </surface>
        </collision>
        <visual name='visual'>
          <geometry>
            <box>
              <size>1 1 1</size>
            </box>
          </geometry>
          <material>
            <script>
              <name>Gazebo/Grey</name>
              <uri>file://media/materials/scripts/gazebo.material</uri>
            </script>
          </material>
        </visual>
        <self_collide>0</self_collide>
        <enable_wind>0</enable_wind>
        <kinematic>0</kinematic>
      </link>
    </model>
    <state world_name='default'>
      <sim_time>258 446000000</sim_time>
      <real_time>306 961502771</real_time>
      <wall_time>1726416632 861526646</wall_time>
      <iterations>258446</iterations>
      <model name='bobo_standalone'>
        <pose>-0.250554 -0.031704 -6.5e-05 3.8e-05 -1.7e-05 -0.368275</pose>
        <scale>1 1 1</scale>
        <link name='base_footprint'>
          <pose>-0.250554 -0.031704 -6.5e-05 3.8e-05 -1.7e-05 -0.368275</pose>
          <velocity>0.005374 -0.002671 -0.000204 -0.023335 -0.043805 -0.000832</velocity>
          <acceleration>-5.19887 1.96582 1.59 -0.49324 0.994139 -0.776377</acceleration>
          <wrench>-10.6894 4.04192 3.2692 0 -0 0</wrench>
        </link>
        <link name='caster_back_left_link'>
          <pose>-0.378141 0.100871 0.015975 -0.002846 -0.030448 0.068067</pose>
          <velocity>0.005538 -0.000336 -0.018728 0.021005 -0.474234 0.007806</velocity>
          <acceleration>13.0884 -1.80224 -33.3253 -0.383098 0.435743 0.081034</acceleration>
          <wrench>0.135952 -0.01872 -0.346156 0 -0 0</wrench>
        </link>
        <link name='caster_back_right_link'>
          <pose>-0.434103 -0.044205 0.015986 -0.065447 0.643219 -0.825737</pose>
          <velocity>0.006714 -0.001 -0.001426 0.068177 0.451389 0.038389</velocity>
          <acceleration>16.858 -0.835494 -4.29462 0.83601 -0.888146 -0.488741</acceleration>
          <wrench>0.175108 -0.008678 -0.044609 0 -0 0</wrench>
        </link>
        <link name='caster_front_left_link'>
          <pose>-0.066987 -0.019196 0.016008 3.11587 -0.28682 2.51522</pose>
          <velocity>0.003762 -0.002853 0.01687 0.178383 0.235086 -0.002377</velocity>
          <acceleration>9.03227 -6.27057 40.0558 -1.16131 -0.747295 -2.62509</acceleration>
          <wrench>0.09382 -0.065134 0.416067 0 -0 0</wrench>
        </link>
        <link name='caster_front_right_link'>
          <pose>-0.122965 -0.164275 0.015974 -0.016267 -0.184252 0.070169</pose>
          <velocity>0.002402 -0.005455 0.00265 0.341901 0.152519 -0.029722</velocity>
          <acceleration>6.47877 -10.4657 4.81865 2.18209 0.017494 1.79059</acceleration>
          <wrench>0.067296 -0.10871 0.050052 0 -0 0</wrench>
        </link>
        <link name='left_wheel_link'>
          <pose>-0.186326 0.136135 0.085341 3.14025 1.54288 2.77198</pose>
          <velocity>0.001709 -0.000701 -0.001285 -0.353974 -0.900943 -0.000706</velocity>
          <acceleration>4.95628 -1.95835 -0.136155 -0.784477 0.425738 -2.48458</acceleration>
          <wrench>5.62379 -2.2221 -0.154493 0 -0 0</wrench>
        </link>
        <link name='right_wheel_link'>
          <pose>-0.31572 -0.199187 0.085326 5.4e-05 -0.561292 -0.368303</pose>
          <velocity>0.001471 -0.000612 0.000849 2.46889 -1.41491 3.14064</velocity>
          <acceleration>4.11266 -1.64179 0.09842 -0.506286 0.274735 -2.80515</acceleration>
          <wrench>4.66655 -1.8629 0.111675 0 -0 0</wrench>
        </link>
      </model>
      <model name='ground_plane'>
        <pose>0 0 0 0 -0 0</pose>
        <scale>1 1 1</scale>
        <link name='link'>
          <pose>0 0 0 0 -0 0</pose>
          <velocity>0 0 0 0 -0 0</velocity>
          <acceleration>0 0 0 0 -0 0</acceleration>
          <wrench>0 0 0 0 -0 0</wrench>
        </link>
      </model>
      <model name='unit_box'>
        <pose>1.81408 -0.506578 0.499995 -1e-05 -0 0</pose>
        <scale>1 1 1</scale>
        <link name='link'>
          <pose>1.81408 -0.506578 0.499995 -1e-05 -0 0</pose>
          <velocity>0 0 0 0 -0 0</velocity>
          <acceleration>0.004709 0.011055 -9.78158 -0.022108 0.009414 1e-06</acceleration>
          <wrench>0.004709 0.011055 -9.78158 0 -0 0</wrench>
        </link>
      </model>
      <model name='unit_box_0'>
        <pose>1.8307 0.6733 0.5 0 -0 0</pose>
        <scale>1 1 1</scale>
        <link name='link'>
          <pose>1.8307 0.6733 0.5 0 -0 0</pose>
          <velocity>0 0 0 0 -0 0</velocity>
          <acceleration>-0.004709 -9.78112 9.78158 0.712677 -0.009414 -4.3e-05</acceleration>
          <wrench>-0.004709 -9.78112 9.78158 0 -0 0</wrench>
        </link>
      </model>
      <light name='sun'>
        <pose>0 0 10 0 -0 0</pose>
      </light>
    </state>
    <gui fullscreen='0'>
      <camera name='user_camera'>
        <pose>6.23761 -2.71459 4.40314 0 0.679643 2.8442</pose>
        <view_controller>orbit</view_controller>
        <projection_type>perspective</projection_type>
      </camera>
    </gui>
  </world>
</sdf>
