<?xml version="1.0" ?>
<!-- =================================================================================== -->
<!-- |    This document was autogenerated by xacro from sim_robot2_complete.urdf.xacro | -->
<!-- |    EDITING THIS FILE BY HAND IS NOT RECOMMENDED                                 | -->
<!-- =================================================================================== -->
<robot name="bobo_standalone">
  <link name="base_footprint"/>
  <joint name="base_joint" type="fixed">
    <origin rpy="0 0 0" xyz="0 0 0"/>
    <parent link="base_footprint"/>
    <child link="base_link"/>
  </joint>
  <link name="base_link">
    <inertial>
      <origin rpy="0 0 0" xyz="0.0046524 -1.2029E-05 0.18162"/>
      <mass value="1.9421"/>
      <inertia ixx="0.016249" ixy="-2.6352E-08" ixz="-0.00032505" iyy="0.019076" iyz="2.2146E-08" izz="0.031848"/>
    </inertial>
    <visual>
      <origin rpy="0 0 0" xyz="0 0 0"/>
      <geometry>
        <mesh filename="/ros2_ws/src/rom_robot_class/bobo_description/meshes/base_link.STL"/>
      </geometry>
      <material name="">
        <color rgba="0.75294 0.75294 0.75294 1"/>
      </material>
    </visual>
    <collision>
      <origin rpy="0 0 0" xyz="0 0 0"/>
      <geometry>
        <mesh filename="/ros2_ws/src/rom_robot_class/bobo_description/meshes/base_link.STL"/>
      </geometry>
    </collision>
  </link>
  <link name="right_wheel_link">
    <inertial>
      <origin rpy="0 0 0" xyz="-6.88469101173261E-10 0.00261076778922063 1.46539359813236E-09"/>
      <mass value="1.13468316605061"/>
      <inertia ixx="0.00214377737472316" ixy="1.35474255028293E-09" ixz="-1.11198689477431E-11" iyy="0.00371288553259231" iyz="-1.63769629423567E-09" izz="0.00214377737749942"/>
    </inertial>
    <visual>
      <origin rpy="0 0 0" xyz="0 0 0"/>
      <geometry>
        <mesh filename="/ros2_ws/src/rom_robot_class/bobo_description/meshes/wheel_right_link.STL"/>
      </geometry>
      <material name="">
        <color rgba="1 1 1 1"/>
      </material>
    </visual>
    <collision>
      <origin rpy="0 0 0" xyz="0 0 0"/>
      <geometry>
        <mesh filename="/ros2_ws/src/rom_robot_class/bobo_description/meshes/wheel_right_link.STL"/>
      </geometry>
    </collision>
  </link>
  <joint name="right_wheel_joint" type="continuous">
    <origin rpy="0 0 0" xyz="-0.0005 -0.17971 0.0854"/>
    <parent link="base_link"/>
    <child link="right_wheel_link"/>
    <axis xyz="0 -1 0"/>
  </joint>
  <link name="left_wheel_link">
    <inertial>
      <origin rpy="0 0 0" xyz="1.61277113885916E-09 -0.00261076778922059 1.42610201425697E-10"/>
      <mass value="1.13468316605061"/>
      <inertia ixx="0.00214377738646834" ixy="2.09699277269092E-09" ixz="-4.27898719562988E-12" iyy="0.00371288553259229" iyz="-3.46407025976004E-10" izz="0.00214377736575422"/>
    </inertial>
    <visual>
      <origin rpy="0 0 0" xyz="0 0 0"/>
      <geometry>
        <mesh filename="/ros2_ws/src/rom_robot_class/bobo_description/meshes/wheel_left_link.STL"/>
      </geometry>
      <material name="">
        <color rgba="1 1 1 1"/>
      </material>
    </visual>
    <collision>
      <origin rpy="0 0 0" xyz="0 0 0"/>
      <geometry>
        <mesh filename="/ros2_ws/src/rom_robot_class/bobo_description/meshes/wheel_left_link.STL"/>
      </geometry>
    </collision>
  </link>
  <joint name="left_wheel_joint" type="continuous">
    <origin rpy="0 0 0" xyz="-0.0005 0.17971 0.0854"/>
    <parent link="base_link"/>
    <child link="left_wheel_link"/>
    <axis xyz="0 -1 0"/>
  </joint>
  <link name="caster_front_right_link">
    <inertial>
      <origin rpy="0 0 0" xyz="-1.38777878078145E-17 -1.38777878078145E-17 -2.77555756156289E-17"/>
      <mass value="0.0103871549572359"/>
      <inertia ixx="9.76068238842766E-07" ixy="4.37487850150777E-08" ixz="4.36668756326797E-23" iyy="1.47229853084168E-06" iyz="5.40669622917979E-22" izz="9.72240768629191E-07"/>
    </inertial>
    <visual>
      <origin rpy="0 0 0" xyz="0 0 0"/>
      <geometry>
        <mesh filename="/ros2_ws/src/rom_robot_class/bobo_description/meshes/caster_front_right_link.STL"/>
      </geometry>
      <material name="">
        <color rgba="1 1 1 1"/>
      </material>
    </visual>
    <collision>
      <origin rpy="0 0 0" xyz="0 0 0"/>
      <geometry>
        <mesh filename="/ros2_ws/src/rom_robot_class/bobo_description/meshes/caster_front_right_link.STL"/>
      </geometry>
    </collision>
  </link>
  <joint name="caster_front_right_joint" type="fixed">
    <origin rpy="0 0 0.43633" xyz="0.16676 -0.077762 0.016"/>
    <parent link="base_link"/>
    <child link="caster_front_right_link"/>
    <axis xyz="-0.087156 -0.99619 0"/>
  </joint>
  <link name="caster_front_left_link">
    <inertial>
      <origin rpy="0 0 0" xyz="-1.38777878078145E-17 -5.55111512312578E-17 0"/>
      <mass value="0.0103871549572359"/>
      <inertia ixx="9.76068447320134E-07" ixy="-4.37499673489831E-08" ixz="3.49242855259726E-23" iyy="1.47229832236431E-06" iyz="-6.51906793689185E-22" izz="9.72240768629191E-07"/>
    </inertial>
    <visual>
      <origin rpy="0 0 0" xyz="0 0 0"/>
      <geometry>
        <mesh filename="/ros2_ws/src/rom_robot_class/bobo_description/meshes/caster_front_left_link.STL"/>
      </geometry>
      <material name="">
        <color rgba="1 1 1 1"/>
      </material>
    </visual>
    <collision>
      <origin rpy="0 0 0" xyz="0 0 0"/>
      <geometry>
        <mesh filename="/ros2_ws/src/rom_robot_class/bobo_description/meshes/caster_front_left_link.STL"/>
      </geometry>
    </collision>
  </link>
  <joint name="caster_front_left_joint" type="fixed">
    <origin rpy="0 0 -0.43633" xyz="0.16676 0.077762 0.016"/>
    <parent link="base_link"/>
    <child link="caster_front_left_link"/>
    <axis xyz="0.087156 -0.99619 0"/>
  </joint>
  <link name="caster_back_left_link">
    <inertial>
      <origin rpy="0 0 0" xyz="0 0 0"/>
      <mass value="0.0103871549572358"/>
      <inertia ixx="9.76068415792723E-07" ixy="4.37497885481657E-08" ixz="-3.74882476298782E-14" iyy="1.47229835389171E-06" iyz="-4.28492630568062E-13" izz="9.72240768629189E-07"/>
    </inertial>
    <visual>
      <origin rpy="0 0 0" xyz="0 0 0"/>
      <geometry>
        <mesh filename="/ros2_ws/src/rom_robot_class/bobo_description/meshes/caster_back_left_link.STL"/>
      </geometry>
      <material name="">
        <color rgba="1 1 1 1"/>
      </material>
    </visual>
    <collision>
      <origin rpy="0 0 0" xyz="0 0 0"/>
      <geometry>
        <mesh filename="/ros2_ws/src/rom_robot_class/bobo_description/meshes/caster_back_left_link.STL"/>
      </geometry>
    </collision>
  </link>
  <joint name="caster_back_left_joint" type="fixed">
    <origin rpy="0 0 0.43633" xyz="-0.16676 0.077762 0.016"/>
    <parent link="base_link"/>
    <child link="caster_back_left_link"/>
    <axis xyz="-0.087156 -0.99619 0"/>
  </joint>
  <link name="caster_back_right_link">
    <inertial>
      <origin rpy="0 0 0" xyz="-5.55111512312578E-17 0 2.77555756156289E-17"/>
      <mass value="0.0103871549572359"/>
      <inertia ixx="9.76068447320135E-07" ixy="-4.37499673489848E-08" ixz="4.3623233005725E-23" iyy="1.47229832236431E-06" iyz="-5.74330631173444E-22" izz="9.72240768629192E-07"/>
    </inertial>
    <visual>
      <origin rpy="0 0 0" xyz="0 0 0"/>
      <geometry>
        <mesh filename="/ros2_ws/src/rom_robot_class/bobo_description/meshes/caster_back_right_link.STL"/>
      </geometry>
      <material name="">
        <color rgba="1 1 1 1"/>
      </material>
    </visual>
    <collision>
      <origin rpy="0 0 0" xyz="0 0 0"/>
      <geometry>
        <mesh filename="/ros2_ws/src/rom_robot_class/bobo_description/meshes/caster_back_right_link.STL"/>
      </geometry>
    </collision>
  </link>
  <joint name="caster_back_right_joint" type="fixed">
    <origin rpy="0 0 -0.43633" xyz="-0.16676 -0.077762 0.016"/>
    <parent link="base_link"/>
    <child link="caster_back_right_link"/>
    <axis xyz="0.087156 -0.99619 0"/>
  </joint>
  <!-- ROM ADD -->
  <!-- LASER -->
  <joint name="laser_joint" type="fixed">
    <parent link="base_link"/>
    <child link="laser_link"/>
    <origin rpy="3.1415926 0 0" xyz="0.18 0 0.24"/>
  </joint>
  <link name="laser_link">
    <visual>
      <origin rpy="0 0 0" xyz="0 0 0.0"/>
      <geometry>
        <box size="0.05 0.05 0.05"/>
      </geometry>
      <material name="red"/>
    </visual>
    <collision>
      <origin rpy="0 0 0" xyz="0.015 0 -0.0065"/>
      <geometry>
        <cylinder length="0.0315" radius="0.055"/>
      </geometry>
    </collision>
    <inertial>
      <mass value="0.114"/>
      <origin xyz="0 0 0"/>
      <inertia ixx="0.001" ixy="0.0" ixz="0.0" iyy="0.001" iyz="0.0" izz="0.001"/>
    </inertial>
  </link>
  <!-- IMU -->
  <joint name="imu_joint" type="fixed">
    <parent link="base_link"/>
    <child link="imu_link"/>
    <origin rpy="0 0 0" xyz="0 0 0.268"/>
  </joint>
  <link name="imu_link">
    <visual>
      <origin rpy="0 0 0" xyz="0 0 0.0"/>
      <geometry>
        <box size="0.03 0.02 0.02"/>
      </geometry>
      <material name="green"/>
    </visual>
  </link>
  <!-- 3D CAM_Left -->
  <joint name="cam3d_left_joint" type="fixed">
    <parent link="base_link"/>
    <child link="cam3d_left_link"/>
    <origin rpy="0 0 0" xyz="0 0.3 0.5"/>
  </joint>
  <link name="cam3d_left_link">
    <visual>
      <origin rpy="0 0 0" xyz="0 0 0.0"/>
      <geometry>
        <box size="0.03 0.02 0.02"/>
      </geometry>
      <material name="blue"/>
    </visual>
  </link>
  <!-- 3D CAM_Right -->
  <joint name="cam3d_right_joint" type="fixed">
    <parent link="base_link"/>
    <child link="cam3d_right_link"/>
    <origin rpy="0 0 0" xyz="0 -0.3 0.5"/>
  </joint>
  <link name="cam3d_right_link">
    <visual>
      <origin rpy="0 0 0" xyz="0 0 0.0"/>
      <geometry>
        <box size="0.03 0.02 0.02"/>
      </geometry>
      <material name="blue"/>
    </visual>
  </link>
  <!-- 3D CAM_Top -->
  <joint name="cam3d_top_joint" type="fixed">
    <parent link="base_link"/>
    <child link="cam3d_top_link"/>
    <origin rpy="0 0 0" xyz="0.15 0 0.8"/>
  </joint>
  <link name="cam3d_top_link">
    <visual>
      <origin rpy="0 0 0" xyz="0 0 0.0"/>
      <geometry>
        <box size="0.03 0.02 0.02"/>
      </geometry>
      <material name="blue"/>
    </visual>
  </link>
  <!-- materials colors for rviz  -->
  <material name="white">
    <color rgba="1 1 1 0.8"/>
  </material>
  <material name="grey">
    <color rgba="0.5 0.5 0.5 1"/>
  </material>
  <material name="light_grey">
    <color rgba="0.6 0.6 0.6 0.7"/>
  </material>
  <material name="dark_grey">
    <color rgba="0.3 0.3 0.3 0.7"/>
  </material>
  <material name="black">
    <color rgba="0.1 0.1 0.1 0.8"/>
  </material>
  <material name="red">
    <color rgba="1 0 0 0.8"/>
  </material>
  <material name="green">
    <color rgba="0 1 0 1"/>
  </material>
  <material name="blue">
    <color rgba="0 0 1 1"/>
  </material>
  <material name="grey_blue">
    <color rgba="0.4 0.4 1.0 0.8"/>
  </material>
  <material name="orange">
    <color rgba="1.0 0.7 0.0 1"/>
  </material>
  <!-- ROM END -->
  <ros2_control name="GazeboSystem" type="system">
    <hardware>
      <plugin>gazebo_ros2_control/GazeboSystem</plugin>
    </hardware>
    <joint name="left_wheel_joint">
      <command_interface name="velocity">
        <param name="min">-50</param>
        <param name="max">50</param>
      </command_interface>
      <state_interface name="velocity"/>
      <state_interface name="position"/>
    </joint>
    <joint name="right_wheel_joint">
      <command_interface name="velocity">
        <param name="min">-50</param>
        <param name="max">50</param>
      </command_interface>
      <state_interface name="velocity"/>
      <state_interface name="position"/>
    </joint>
  </ros2_control>
  <gazebo>
    <plugin filename="libgazebo_ros2_control.so" name="gazebo_ros2_control">
      <robot_param>robot_description</robot_param>
      <robot_param_node>robot_state_publisher</robot_param_node>
      <parameters>/ros2_ws/install/bobo_description/share/bobo_description/sim_config/my_controllers.yaml</parameters>
      <!-- Output -->
      <odometry_frame>odom</odometry_frame>
      <robot_base_frame>base_footprint</robot_base_frame>
      <publish_odom>true</publish_odom>
      <publish_odom_tf>true</publish_odom_tf>
      <publish_wheel_tf>true</publish_wheel_tf>
    </plugin>
  </gazebo>
  <gazebo reference="imu_link">
    <gravity>true</gravity>
    <sensor name="imu_sensor" type="imu">
      <always_on>true</always_on>
      <update_rate>20</update_rate>
      <visualize>true</visualize>
      <topic>/imu</topic>
      <plugin filename="libgazebo_ros_imu_sensor.so" name="imu_plugin">
        <topicName>imu</topicName>
        <bodyName>imu_link</bodyName>
        <updateRateHZ>10.0</updateRateHZ>
        <gaussianNoise>0.0</gaussianNoise>
        <xyzOffset>0 0 0</xyzOffset>
        <rpyOffset>0 0 0</rpyOffset>
        <frameName>imu_link</frameName>
        <initialOrientationAsReference>false</initialOrientationAsReference>
      </plugin>
      <pose>0 0 0 0 0 0</pose>
    </sensor>
  </gazebo>
  <gazebo reference="laser_link">
    <material>Gazebo/Red</material>
    <sensor name="laser" type="ray">
      <pose>0 0 0 0 0 0</pose>
      <visualize>true</visualize>
      <update_rate>10</update_rate>
      <ray>
        <scan>
          <horizontal>
            <samples>360</samples>
            <resolution>1</resolution>
            <min_angle>-2.3562</min_angle>
            <!-- -3.14 -->
            <max_angle>2.3562</max_angle>
            <!-- 3.14 -->
          </horizontal>
        </scan>
        <range>
          <min>0.1</min>
          <!-- 0.3 -->
          <max>12</max>
          <!-- 12 -->
          <resolution>0.01</resolution>
        </range>
      </ray>
      <plugin filename="libgazebo_ros_ray_sensor.so" name="laser_controller">
        <ros>
          <argument>~/out:=scan</argument>
        </ros>
        <output_type>sensor_msgs/LaserScan</output_type>
        <frame_name>laser_link</frame_name>
      </plugin>
    </sensor>
  </gazebo>

  <!-- LEFT CAMERA -->
  <joint name="camera_optical_joint_left" type="fixed">
        <parent link="cam3d_left_link"/>
        <child link="camera_link_optical_left"/>
        <origin xyz="0 0 0" rpy="-1.57075 0 -1.57075"/> <!-- ${-pi/2} -->
    </joint>
    <link name="camera_link_optical_left"></link>

    <gazebo reference="cam3d_left_link">
        <material>Gazebo/Blue</material>
        <sensor name="camera_left" type="depth">
            <pose>0 0 0 0 0 0</pose>
            <visualize>true</visualize>
            <update_rate>10</update_rate>
            <camera>
                <horizontal_fov>1.089</horizontal_fov>
                <image>
                    <format>B8G8R8</format>
                    <width>640</width>
                    <height>480</height>
                </image>
                <clip>
                    <near>0.05</near>
                    <far>8.0</far>
                </clip>
            </camera>
            <plugin name="camera_controller_left" filename="libgazebo_ros_camera.so">
                <frame_name>camera_link_optical_left</frame_name>
                <min_depth>0.1</min_depth>
                <max_depth>50</max_depth>
            </plugin>
        </sensor>
    </gazebo>

      <!-- RIGHT CAMERA -->
  <joint name="camera_optical_joint_right" type="fixed">
        <parent link="cam3d_right_link"/>
        <child link="camera_link_optical_right"/>
        <origin xyz="0 0 0" rpy="-1.57075 0 -1.57075"/> <!-- ${-pi/2} -->
    </joint>
    <link name="camera_link_optical_right"></link>

    <gazebo reference="cam3d_right_link_right">
        <material>Gazebo/Blue</material>
        <sensor name="camera_right" type="depth">
            <pose>0 0 0 0 0 0</pose>
            <visualize>true</visualize>
            <update_rate>10</update_rate>
            <camera>
                <horizontal_fov>1.089</horizontal_fov>
                <image>
                    <format>B8G8R8</format>
                    <width>640</width>
                    <height>480</height>
                </image>
                <clip>
                    <near>0.05</near>
                    <far>8.0</far>
                </clip>
            </camera>
            <plugin name="camera_controller_right" filename="libgazebo_ros_camera.so">
                <frame_name>camera_link_optical_right</frame_name>
                <min_depth>0.1</min_depth>
                <max_depth>50</max_depth>
            </plugin>
        </sensor>
    </gazebo>

      <!-- TOP CAMERA -->
  <joint name="camera_optical_joint" type="fixed">
        <parent link="cam3d_top_link"/>
        <child link="camera_link_optical"/>
        <origin xyz="0 0 0" rpy="-1.57075 0 -1.57075"/> <!-- ${-pi/2} -->
    </joint>
    <link name="camera_link_optical"></link>

    <gazebo reference="cam3d_top_link">
        <material>Gazebo/Blue</material>
        <sensor name="camera_top" type="depth">
            <pose>0 0 0 0 0 0</pose>
            <visualize>true</visualize>
            <update_rate>10</update_rate>
            <camera>
                <horizontal_fov>1.089</horizontal_fov>
                <image>
                    <format>B8G8R8</format>
                    <width>640</width>
                    <height>480</height>
                </image>
                <clip>
                    <near>0.05</near>
                    <far>8.0</far>
                </clip>
            </camera>
            <plugin name="camera_controller_top" filename="libgazebo_ros_camera.so">
                <frame_name>camera_link_optical</frame_name>
                <min_depth>0.1</min_depth>
                <max_depth>50</max_depth>
            </plugin>
        </sensor>
    </gazebo>

</robot>
