<?xml version="1.0" ?>

<robot xmlns:xacro="http://ros.org/wiki/xacro">
  <xacro:property name="M_PI" value="3.1415926535897931" /> 
  
    <link name="base_footprint"/>
    <joint name="base_joint" type="fixed">
      <origin xyz="0 0 0.0102" rpy="0 0 0" />
      <parent link="base_footprint"/>
      <child link="base_link" />
    </joint>
    <link name="base_link">
      <visual>
        <geometry>
          <!-- new mesh -->
          <cylinder length="0.24" radius="0.24" />
        </geometry>
        <origin xyz="0 0 0.15" rpy="0 0 0"/>
        <material name="black"/>
      </visual>
      <collision name="base">
        <geometry>
          <cylinder length="0.24" radius="0.24"/>
        </geometry>
        <origin xyz="0.0 0 0.15" rpy="0 0 0"/>
      </collision>
      <inertial>
        <origin xyz="0.01 0 0"/>
        <mass value="2.4"/>
        <inertia ixx="0.019995" ixy="0.0" ixz="0.0"
                 iyy="0.019995" iyz="0.0"
                 izz="0.03675" />
      </inertial>
    </link>

    <joint name="wheel_left_joint" type="continuous">
      <parent link="base_link"/>
      <child link="wheel_left_link"/>
      <origin xyz="0.00 ${0.36/2} 0.02" rpy="${-M_PI/2} 0 0"/>
      <axis xyz="0 0 1"/>
    </joint>
    <link name="wheel_left_link">
      <visual>
        <geometry>
          <cylinder length="0.0276" radius="0.0848" />
        </geometry>
        <origin xyz="0 -0.03 0" rpy="0 0 0"/>
        <material name="black"/>
      </visual>
      <collision>
        <geometry>
          <cylinder length="0.0276" radius="0.0848"/>
        </geometry>
        <origin rpy="0 0 0" xyz="0 0 0"/>
      </collision>
      <inertial>
        <mass value="0.01" />
        <origin xyz="0 0 0" />
        <inertia ixx="0.001" ixy="0.0" ixz="0.0"
                 iyy="0.001" iyz="0.0"
                 izz="0.001" />
      </inertial>
    </link>

    <joint name="wheel_right_joint" type="continuous">
      <parent link="base_link"/>
      <child link="wheel_right_link"/>
      <origin xyz="0.00 -${0.36/2} 0.02" rpy="${-M_PI/2} 0 0"/>
      <axis xyz="0 0 1"/>
    </joint>
    <link name="wheel_right_link">
      <visual>
        <geometry>
          <cylinder length="0.0276" radius="0.0848" />
        </geometry>
        <origin xyz="0 -0.03 0" rpy="0 0 0"/>
        <material name="black"/>
      </visual>
      <collision>
        <geometry>
          <cylinder length="0.0276" radius="0.0848"/>
        </geometry>
        <origin rpy="0 0 0" xyz="0 0 0"/>
      </collision>
      <inertial>
        <mass value="0.01" />
        <origin xyz="0 0 0" />
        <inertia ixx="0.001" ixy="0.0" ixz="0.0"
                 iyy="0.001" iyz="0.0"
                 izz="0.001" />
      </inertial>
    </link>

    <joint name="caster_front_joint" type="fixed">
      <parent link="base_link"/>
      <child link="caster_front_link"/>
      <origin xyz="0.17 0.0 0.02" rpy="${-M_PI/2} 0 0"/>
    </joint>
    <link name="caster_front_link">
      <visual>
        <geometry>
          <cylinder length="0.0276" radius="0.035"/>
        </geometry>
        <origin xyz="0 0 0" rpy="0 0 0"/>
        <material name="black"/>
      </visual>
      <collision>
        <geometry>
          <cylinder length="0.0276" radius="0.035"/>
        </geometry>
        <origin rpy="0 0 0" xyz="0 0 0"/>
      </collision>
      <inertial>
        <mass value="0.01" />
        <origin xyz="0 0 0" />
        <inertia ixx="0.001" ixy="0.0" ixz="0.0"
                 iyy="0.001" iyz="0.0"
                 izz="0.001" />
      </inertial>
    </link>

    <joint name="caster_back_joint" type="fixed">
      <parent link="base_link"/>
      <child link="caster_back_link"/>
      <origin xyz="-0.17 0.0 0.02" rpy="${-M_PI/2} 0 0"/>
    </joint>
    <link name="caster_back_link">
      <visual>
        <geometry>
          <cylinder length="0.0276" radius="0.035"/>
        </geometry>
        <origin xyz="0 0 0" rpy="0 0 0"/>
        <material name="black"/>
      </visual>
      <collision>
        <geometry>
          <cylinder length="0.0276" radius="0.035"/>
        </geometry>
        <origin rpy="0 0 0" xyz="0 0 0"/>
      </collision>
      <inertial>
        <mass value="0.01" />
        <origin xyz="0 0 0" />
        <inertia ixx="0.001" ixy="0.0" ixz="0.0"
                 iyy="0.001" iyz="0.0"
                 izz="0.001" />
      </inertial>
    </link>

    <joint name="imu_joint" type="fixed">
      <parent link="base_link"/>
      <child link="imu_link"/>
      <origin xyz="0 0 0.268" rpy="0 0 0"/>
    </joint>

    <link name="imu_link">
      <visual>
        <origin xyz="0 0 0.0" rpy="0 0 0"/>
        <geometry>
          <box size="0.03 0.02 0.02"/>
        </geometry>
        <material name="red"/>
      </visual>
    </link>

    <joint name="laser_joint" type="fixed">
      <parent link="base_link"/>
      <child link="laser_link"/>
      <origin xyz="0.18 0 0.24" rpy="3.1415926 0 0"/>
    </joint>

    <link name="laser_link">
      <visual>
        <origin xyz="0 0 0.0" rpy="0 0 0"/>
        <geometry>
          <box size="0.05 0.05 0.05"/>
        </geometry>
        <material name="grey_blue"/>
      </visual>

      <collision>
        <origin xyz="0.015 0 -0.0065" rpy="0 0 0"/>
        <geometry>
          <cylinder length="0.0315" radius="0.055"/>
        </geometry>
      </collision>

      <inertial>
        <mass value="0.114" />
        <origin xyz="0 0 0" />
        <inertia ixx="0.001" ixy="0.0" ixz="0.0"
                 iyy="0.001" iyz="0.0"
                 izz="0.001" />
      </inertial>
    </link>
  
  <material name="white">
    <color rgba="1 1 1 0.8"/>
  </material>

  <material name="grey">
    <color rgba="0.5 0.5 0.5 1"/>
  </material>

  <material name="light_grey">
    <color rgba="0.6 0.6 0.6 0.7"/>
  </material>

  <material name="dark_grey">
    <color rgba="0.3 0.3 0.3 0.7"/>
  </material>

  <material name="black">
    <color rgba="0.1 0.1 0.1 0.8"/>
  </material>

  <material name="red">
    <color rgba="1 0 0 0.8"/>
  </material>

  <material name="green">
    <color rgba="0.0 0.8 0.0 1"/>
  </material>

  <material name="blue">
    <color rgba="0.0 0.0 1.0 1"/>
  </material>

  <material name="grey_blue">
    <color rgba="0.4 0.4 1.0 0.8"/>
  </material>

  <material name="orange">
    <color rgba="1.0 0.7 0.0 1"/>
  </material>
  
</robot>
